Workbook

Sheet Heartbeat Graph
A1: Time | B1: Minutes | C1: Tension (0-100) | D1: Event | E1: Event Type | F1: Intensity Change | G1: Designer Notes | H1: Est. Level
A2: 0:00 | B2: 0 | C2: 20 | H2: =IFERROR(INDEX('Level Up Estimate'!$H$33:'Level Up Estimate'!$H$63,MATCH(B2,'Level Up Estimate'!$B$33:'Level Up Estimate'!$B$63,0)),"")
A3: 0:30 | B3: 0.5 | C3: 28 | H3: =IFERROR(INDEX('Level Up Estimate'!$H$33:'Level Up Estimate'!$H$63,MATCH(B3,'Level Up Estimate'!$B$33:'Level Up Estimate'!$B$63,0)),"")
A4: 1:00 | B4: 1 | C4: 36 | H4: =IFERROR(INDEX('Level Up Estimate'!$H$33:'Level Up Estimate'!$H$63,MATCH(B4,'Level Up Estimate'!$B$33:'Level Up Estimate'!$B$63,0)),"")
A5: 1:30 | B5: 1.5 | C5: 42 | H5: =IFERROR(INDEX('Level Up Estimate'!$H$33:'Level Up Estimate'!$H$63,MATCH(B5,'Level Up Estimate'!$B$33:'Level Up Estimate'!$B$63,0)),"")
A6: 2:00 | B6: 2 | C6: 65 | D6: Zone Objective #1 | E6: Zone | F6: +25 spike | H6: =IFERROR(INDEX('Level Up Estimate'!$H$33:'Level Up Estimate'!$H$63,MATCH(B6,'Level Up Estimate'!$B$33:'Level Up Estimate'!$B$63,0)),"")
A7: 2:30 | B7: 2.5 | C7: 50 | H7: =IFERROR(INDEX('Level Up Estimate'!$H$33:'Level Up Estimate'!$H$63,MATCH(B7,'Level Up Estimate'!$B$33:'Level Up Estimate'!$B$63,0)),"")
A8: 3:00 | B8: 3 | C8: 45 | H8: =IFERROR(INDEX('Level Up Estimate'!$H$33:'Level Up Estimate'!$H$63,MATCH(B8,'Level Up Estimate'!$B$33:'Level Up Estimate'!$B$63,0)),"")
A9: 3:30 | B9: 3.5 | C9: 48 | H9: =IFERROR(INDEX('Level Up Estimate'!$H$33:'Level Up Estimate'!$H$63,MATCH(B9,'Level Up Estimate'!$B$33:'Level Up Estimate'!$B$63,0)),"")
A10: 4:00 | B10: 4 | C10: 55 | H10: =IFERROR(INDEX('Level Up Estimate'!$H$33:'Level Up Estimate'!$H$63,MATCH(B10,'Level Up Estimate'!$B$33:'Level Up Estimate'!$B$63,0)),"")
A11: 4:30 | B11: 4.5 | C11: 62 | D11: Level Up | E11: Level Up | F11: +20 pause | H11: =IFERROR(INDEX('Level Up Estimate'!$H$33:'Level Up Estimate'!$H$63,MATCH(B11,'Level Up Estimate'!$B$33:'Level Up Estimate'!$B$63,0)),"")
A12: 5:00 | B12: 5 | C12: 82 | D12: Mini Boss #1 | E12: Mini Boss | F12: +40 spike | H12: =IFERROR(INDEX('Level Up Estimate'!$H$33:'Level Up Estimate'!$H$63,MATCH(B12,'Level Up Estimate'!$B$33:'Level Up Estimate'!$B$63,0)),"")
A13: 5:30 | B13: 5.5 | C13: 48 | H13: =IFERROR(INDEX('Level Up Estimate'!$H$33:'Level Up Estimate'!$H$63,MATCH(B13,'Level Up Estimate'!$B$33:'Level Up Estimate'!$B$63,0)),"")
A14: 6:00 | B14: 6 | C14: 68 | D14: Zone Objective #2 | E14: Zone | F14: +20 spike | H14: =IFERROR(INDEX('Level Up Estimate'!$H$33:'Level Up Estimate'!$H$63,MATCH(B14,'Level Up Estimate'!$B$33:'Level Up Estimate'!$B$63,0)),"")
A15: 6:30 | B15: 6.5 | C15: 52 | H15: =IFERROR(INDEX('Level Up Estimate'!$H$33:'Level Up Estimate'!$H$63,MATCH(B15,'Level Up Estimate'!$B$33:'Level Up Estimate'!$B$63,0)),"")
A16: 7:00 | B16: 7 | C16: 55 | H16: =IFERROR(INDEX('Level Up Estimate'!$H$33:'Level Up Estimate'!$H$63,MATCH(B16,'Level Up Estimate'!$B$33:'Level Up Estimate'!$B$63,0)),"")
A17: 7:30 | B17: 7.5 | C17: 58 | H17: =IFERROR(INDEX('Level Up Estimate'!$H$33:'Level Up Estimate'!$H$63,MATCH(B17,'Level Up Estimate'!$B$33:'Level Up Estimate'!$B$63,0)),"")
A18: 8:00 | B18: 8 | C18: 68 | D18: Zone Objective #3 | E18: Zone | F18: +20 spike | H18: =IFERROR(INDEX('Level Up Estimate'!$H$33:'Level Up Estimate'!$H$63,MATCH(B18,'Level Up Estimate'!$B$33:'Level Up Estimate'!$B$63,0)),"")
A19: 8:30 | B19: 8.5 | C19: 55 | H19: =IFERROR(INDEX('Level Up Estimate'!$H$33:'Level Up Estimate'!$H$63,MATCH(B19,'Level Up Estimate'!$B$33:'Level Up Estimate'!$B$63,0)),"")
A20: 9:00 | B20: 9 | C20: 60 | H20: =IFERROR(INDEX('Level Up Estimate'!$H$33:'Level Up Estimate'!$H$63,MATCH(B20,'Level Up Estimate'!$B$33:'Level Up Estimate'!$B$63,0)),"")
A21: 9:30 | B21: 9.5 | C21: 65 | H21: =IFERROR(INDEX('Level Up Estimate'!$H$33:'Level Up Estimate'!$H$63,MATCH(B21,'Level Up Estimate'!$B$33:'Level Up Estimate'!$B$63,0)),"")
A22: 10:00 | B22: 10 | C22: 87 | D22: Mini Boss #2 | E22: Mini Boss | F22: +45 spike | H22: =IFERROR(INDEX('Level Up Estimate'!$H$33:'Level Up Estimate'!$H$63,MATCH(B22,'Level Up Estimate'!$B$33:'Level Up Estimate'!$B$63,0)),"")
A23: 10:30 | B23: 10.5 | C23: 52 | H23: =IFERROR(INDEX('Level Up Estimate'!$H$33:'Level Up Estimate'!$H$63,MATCH(B23,'Level Up Estimate'!$B$33:'Level Up Estimate'!$B$63,0)),"")
A24: 11:00 | B24: 11 | C24: 58 | H24: =IFERROR(INDEX('Level Up Estimate'!$H$33:'Level Up Estimate'!$H$63,MATCH(B24,'Level Up Estimate'!$B$33:'Level Up Estimate'!$B$63,0)),"")
A25: 11:30 | B25: 11.5 | C25: 62 | H25: =IFERROR(INDEX('Level Up Estimate'!$H$33:'Level Up Estimate'!$H$63,MATCH(B25,'Level Up Estimate'!$B$33:'Level Up Estimate'!$B$63,0)),"")
A26: 12:00 | B26: 12 | C26: 72 | D26: Zone Objective #4 | E26: Zone | F26: +25 spike | H26: =IFERROR(INDEX('Level Up Estimate'!$H$33:'Level Up Estimate'!$H$63,MATCH(B26,'Level Up Estimate'!$B$33:'Level Up Estimate'!$B$63,0)),"")
A27: 12:30 | B27: 12.5 | C27: 65 | H27: =IFERROR(INDEX('Level Up Estimate'!$H$33:'Level Up Estimate'!$H$63,MATCH(B27,'Level Up Estimate'!$B$33:'Level Up Estimate'!$B$63,0)),"")
A28: 13:00 | B28: 13 | C28: 75 | H28: =IFERROR(INDEX('Level Up Estimate'!$H$33:'Level Up Estimate'!$H$63,MATCH(B28,'Level Up Estimate'!$B$33:'Level Up Estimate'!$B$63,0)),"")
A29: 13:30 | B29: 13.5 | C29: 82 | H29: =IFERROR(INDEX('Level Up Estimate'!$H$33:'Level Up Estimate'!$H$63,MATCH(B29,'Level Up Estimate'!$B$33:'Level Up Estimate'!$B$63,0)),"")
A30: 14:00 | B30: 14 | C30: 85 | H30: =IFERROR(INDEX('Level Up Estimate'!$H$33:'Level Up Estimate'!$H$63,MATCH(B30,'Level Up Estimate'!$B$33:'Level Up Estimate'!$B$63,0)),"")
A31: 14:30 | B31: 14.5 | C31: 92 | D31: Warning Phase | E31: System | F31: sustained high | H31: =IFERROR(INDEX('Level Up Estimate'!$H$33:'Level Up Estimate'!$H$63,MATCH(B31,'Level Up Estimate'!$B$33:'Level Up Estimate'!$B$63,0)),"")
A32: 15:00 | B32: 15 | C32: 97 | D32: ⚔ MAIN BOSS | E32: Main Boss | F32: +50 climax | H32: =IFERROR(INDEX('Level Up Estimate'!$H$33:'Level Up Estimate'!$H$63,MATCH(B32,'Level Up Estimate'!$B$33:'Level Up Estimate'!$B$63,0)),"")

Sheet Event Schedule
A1: Time | B1: Event Name | C1: Type | D1: Duration | E1: Tension Impact | F1: Reward | G1: Notes
A2: 0:00 | B2: Game Start | C2: System | D2: — | E2: Baseline 20 | F2: — | G2: ผู้เล่นเริ่มคุ้นเคยกับ controls
A3: 2:00 | B3: Zone Objective #1 | C3: Zone | D3: 60s | E3: +30 spike | F3: EXP Bonus ×1.5 (30s) | G3: ต้องยืนบน zone อย่างน้อย 1 คน
A4: 4:30 | B4: Level Up #1 | C4: Level Up | D4: ~15s | E4: +20 pause | F4: Upgrade Card (3 choices) | G4: เกมหยุด timeScale=0 รอเลือก
A5: 5:00 | B5: Mini Boss #1 | C5: Mini Boss | D5: 60-90s | E5: +40 spike | F5: EXP Orb ×10 | G5: HP = wave HP × 5
A6: 6:00 | B6: Zone Objective #2 | C6: Zone | D6: 60s | E6: +25 spike | F6: Heal 30% HP | G6: —
A7: 8:00 | B7: Zone Objective #3 | C7: Zone | D7: 60s | E7: +25 spike | F7: EXP Bonus ×1.5 (30s) | G7: —
A8: 10:00 | B8: Mini Boss #2 | C8: Mini Boss | D8: 90-120s | E8: +45 spike | F8: EXP Orb ×15 | G8: HP = wave HP × 7, มี AoE
A9: 12:00 | B9: Zone Objective #4 | C9: Zone | D9: 60s | E9: +30 spike | F9: Synergy Recipe Hint | G9: แสดง recipe ที่ใกล้ครบ
A10: 14:00 | B10: Warning Phase | C10: System | D10: 60s | E10: +30 build | F10: — | G10: เพลงเปลี่ยน, enemy หนาขึ้น
A11: 15:00 | B11: ⚔ Main Boss | C11: Main Boss | D11: 3-5 min | E11: +50 climax | F11: WIN condition | G11: Phase 1→2→3, Circle+Line AoE

Sheet Design Rules
A1: Heartbeat Graph — Design Rules
A2: Rule # | B2: Rule Name | C2: Description | D2: In-Game Example | E2: Priority | F2: Status | G2: Notes
A3: 1 | B3: Peak & Valley | C3: หลัง tension spike ทุกครั้งต้องมี relief ช่วงสั้นๆ ก่อน spike ถัดไป | D3: Mini Boss ตาย → เงียบ 30s → wave ปกติ | E3: Critical | F3: ✅ Implemented | G3: ห้ามมี spike ติดกัน 2 อัน
A4: 2 | B4: Escalation Ceiling | C4: tension สูงสุดต้องเพิ่มขึ้นทุก 5 นาที | D4: 5min max=82, 10min max=87, 15min=97 | E4: Critical | F4: ✅ Implemented | G4: ให้ความรู้สึกว่าเดิมพันสูงขึ้น
A5: 3 | B5: Pause Rhythm | C5: Level Up pause ทุกๆ ~2 นาทีช่วยให้ผู้เล่นหายใจ | D5: timeScale=0 ระหว่างเลือก upgrade card | E5: High | F5: ✅ Implemented | G5: อย่าให้ pause นานเกิน 30s
A6: 4 | B6: Anticipation Build | C6: ก่อน big event ต้องมี build-up ที่จับสังเกตได้ | D6: tension ขึ้นจาก 65→92 ใน 2:30 นาทีก่อน boss | E6: High | F6: 🔲 Planned | G6: เพลง + visual cue
A7: 5 | B7: Relief Reward | C7: หลัง high tension ต้องมี reward ที่จับต้องได้ชัดเจน | D7: Boss ตาย → EXP orb ฝน + ดนตรีเปลี่ยน | E7: Critical | F7: 🔲 Planned | G7: ให้ dopamine hit ทันที
A8: 6 | B8: Player Agency | C8: ผู้เล่นต้องรู้สึกว่าตัวเองมีอำนาจในการตัดสินใจ | D8: Upgrade choice, positioning ใน Zone | E8: High | F8: ✅ Implemented | G8: อย่าให้ RNG มากเกิน
A9: 7 | B9: Solo/Multi Scaling | C9: mechanic ทุกอย่างต้องทำงานได้ทั้ง 1-4 คน | D9: Boss HP × player count, Zone size scale | E9: Critical | F9: 🔲 Planned | G9: Solo = ง่ายกว่า, 4P = chaos

Sheet Level Up Estimate
A1: ⚙ Assumptions
A3: Base EXP to Level | B3: 100 | C3: EXP | D3: SharedExperienceManager.baseExpToLevel
A4: EXP Growth Rate | B4: 1.25 | C4: multiplier | D4: SharedExperienceManager.expGrowthRate
A5: Base Enemy EXP | B5: 10 | C5: EXP/kill | D5: ค่า base ก่อน wave scaling
A6: Enemy Spawn Rate | B6: 1.5 | C6: seconds/enemy | D6: baseSpawnRate ใน EnemySpawner
A7: Zone Objective Bonus | B7: 1.5 | C7: multiplier | D7: EXP Bonus เมื่อทำ zone สำเร็จ
A8: Zone Bonus Duration | B8: 30 | C8: seconds | D8: ระยะเวลา EXP bonus
A9: Wave EXP Mult/Wave | B9: 0.15 | C9: +% per wave | D9: expMultPerWave
A10: Wave Duration | B10: 60 | C10: seconds | D10: ก่อนขึ้น wave ถัดไป
A11: Player Count | B11: 2 | C11: players | D11: ส่งผลต่อ enemy ที่ฆ่าได้ต่อนาที
A13: 📊 EXP Required per Level
A14: Level | B14: EXP to Next | C14: Cumulative EXP | D14: Notes
A15: 1 | B15: =INT($B$3*$B$4^(A15-1)) | C15: 0
A16: 2 | B16: =INT($B$3*$B$4^(A16-1)) | C16: =C15+B15
A17: 3 | B17: =INT($B$3*$B$4^(A17-1)) | C17: =C16+B16
A18: 4 | B18: =INT($B$3*$B$4^(A18-1)) | C18: =C17+B17
A19: 5 | B19: =INT($B$3*$B$4^(A19-1)) | C19: =C18+B18 | D19: Mini Boss territory
A20: 6 | B20: =INT($B$3*$B$4^(A20-1)) | C20: =C19+B19
A21: 7 | B21: =INT($B$3*$B$4^(A21-1)) | C21: =C20+B20
A22: 8 | B22: =INT($B$3*$B$4^(A22-1)) | C22: =C21+B21
A23: 9 | B23: =INT($B$3*$B$4^(A23-1)) | C23: =C22+B22
A24: 10 | B24: =INT($B$3*$B$4^(A24-1)) | C24: =C23+B23 | D24: Mid-game
A25: 11 | B25: =INT($B$3*$B$4^(A25-1)) | C25: =C24+B24
A26: 12 | B26: =INT($B$3*$B$4^(A26-1)) | C26: =C25+B25
A27: 13 | B27: =INT($B$3*$B$4^(A27-1)) | C27: =C26+B26
A28: 14 | B28: =INT($B$3*$B$4^(A28-1)) | C28: =C27+B27
A29: 15 | B29: =INT($B$3*$B$4^(A29-1)) | C29: =C28+B28 | D29: Late game
A31: ⏱ Timeline EXP Model (per 30 seconds)
A32: Time | B32: Minutes | C32: Wave # | D32: EXP/min (base) | E32: Zone Bonus Active | F32: EXP Gained (30s) | G32: Total EXP | H32: Est. Level
A33: 0:00 | B33: 0 | C33: =INT(B33/$B$10)+1 | D33: =(60/$B$6)*$B$5*$B$11*(1+(C33-1)*$B$9) | F33: =IF(E33="✓",D33/2*$B$7,D33/2) | G33: =F33 | H33: =IFERROR(MATCH(G33,$C$15:$C$29,1),1)
A34: 0:30 | B34: 0.5 | C34: =INT(B34/$B$10)+1 | D34: =(60/$B$6)*$B$5*$B$11*(1+(C34-1)*$B$9) | F34: =IF(E34="✓",D34/2*$B$7,D34/2) | G34: =G33+F34 | H34: =IFERROR(MATCH(G34,$C$15:$C$29,1),1)
A35: 1:00 | B35: 1 | C35: =INT(B35/$B$10)+1 | D35: =(60/$B$6)*$B$5*$B$11*(1+(C35-1)*$B$9) | F35: =IF(E35="✓",D35/2*$B$7,D35/2) | G35: =G34+F35 | H35: =IFERROR(MATCH(G35,$C$15:$C$29,1),1)
A36: 1:30 | B36: 1.5 | C36: =INT(B36/$B$10)+1 | D36: =(60/$B$6)*$B$5*$B$11*(1+(C36-1)*$B$9) | F36: =IF(E36="✓",D36/2*$B$7,D36/2) | G36: =G35+F36 | H36: =IFERROR(MATCH(G36,$C$15:$C$29,1),1)
A37: 2:00 | B37: 2 | C37: =INT(B37/$B$10)+1 | D37: =(60/$B$6)*$B$5*$B$11*(1+(C37-1)*$B$9) | E37: ✓ | F37: =IF(E37="✓",D37/2*$B$7,D37/2) | G37: =G36+F37 | H37: =IFERROR(MATCH(G37,$C$15:$C$29,1),1)
A38: 2:30 | B38: 2.5 | C38: =INT(B38/$B$10)+1 | D38: =(60/$B$6)*$B$5*$B$11*(1+(C38-1)*$B$9) | E38: ✓ | F38: =IF(E38="✓",D38/2*$B$7,D38/2) | G38: =G37+F38 | H38: =IFERROR(MATCH(G38,$C$15:$C$29,1),1)
A39: 3:00 | B39: 3 | C39: =INT(B39/$B$10)+1 | D39: =(60/$B$6)*$B$5*$B$11*(1+(C39-1)*$B$9) | F39: =IF(E39="✓",D39/2*$B$7,D39/2) | G39: =G38+F39 | H39: =IFERROR(MATCH(G39,$C$15:$C$29,1),1)
A40: 3:30 | B40: 3.5 | C40: =INT(B40/$B$10)+1 | D40: =(60/$B$6)*$B$5*$B$11*(1+(C40-1)*$B$9) | F40: =IF(E40="✓",D40/2*$B$7,D40/2) | G40: =G39+F40 | H40: =IFERROR(MATCH(G40,$C$15:$C$29,1),1)
A41: 4:00 | B41: 4 | C41: =INT(B41/$B$10)+1 | D41: =(60/$B$6)*$B$5*$B$11*(1+(C41-1)*$B$9) | F41: =IF(E41="✓",D41/2*$B$7,D41/2) | G41: =G40+F41 | H41: =IFERROR(MATCH(G41,$C$15:$C$29,1),1)
A42: 4:30 | B42: 4.5 | C42: =INT(B42/$B$10)+1 | D42: =(60/$B$6)*$B$5*$B$11*(1+(C42-1)*$B$9) | F42: =IF(E42="✓",D42/2*$B$7,D42/2) | G42: =G41+F42 | H42: =IFERROR(MATCH(G42,$C$15:$C$29,1),1)
A43: 5:00 | B43: 5 | C43: =INT(B43/$B$10)+1 | D43: =(60/$B$6)*$B$5*$B$11*(1+(C43-1)*$B$9) | F43: =IF(E43="✓",D43/2*$B$7,D43/2) | G43: =G42+F43 | H43: =IFERROR(MATCH(G43,$C$15:$C$29,1),1)
...
